Workbook

Sheet All-Hands Attendance
A1: Phone Number | B1: School ID | C1: Name | D1: Email | E1: Mentor Name | F1: Nov. or Exp. | G1: Year in DECA | H1: Pod # 0 | I1: 45917 | J1: 45924 | K1: 45931 | L1: 45938 | M1: 45945 | N1: 45952 | O1: 45959 | P1: 45966 | Q1: 45973 | R1: 45980 | S1: 45994 | T1: 46001 | U1: =T1+28 -> 46029 | V1: =U1+7 -> 46036 | W1: =V1+7 -> 46043 | X1: =W1+7 -> 46050 | Y1: =X1+7 -> 46057 | Z1: =Y1+7 -> 46064 | AA1: =Z1+28 -> 46092
C2: Amber Chang | D2: ambery.chang@warriorlife.net | E2: Aaron Vu | F2: N | G2: 1st Year | H2: 1 | I2: 1 | J2: 1 | K2: 1 | L2: 1 | M2: 1 | N2: 1 | O2: 1 | P2: 1 | Q2: 1 | R2: 1 | S2: 1 | T2: 1 | U2: 1 | V2: 1 | W2: 1 | X2: 1 | Y2: 1 | Z2: 1 | AA2: 1
C3: Nina Ling | D3: nina.ling@warriorlife.net | E3: Aaron Vu | F3: N | G3: 1st Year | H3: 1 | I3: 1 | J3: 1 | K3: 1 | L3: 1 | M3: 1 | N3: 1 | O3: 1 | P3: 1 | Q3: 1 | R3: 1 | S3: 1 | T3: 1 | U3: 1 | V3: 1 | W3: 1 | X3: 1 | Y3: 1 | Z3: 1 | AA3: 1
C4: Elize Kaldani | D4: elize.kaldani@warriorlife.net | E4: Aaron Vu | F4: N | G4: 1st Year | H4: 1 | I4: 1 | J4: 1 | K4: 1 | L4: 1 | M4: 1 | N4: 1 | O4: 1 | P4: 1 | Q4: 1 | R4: 1 | S4: 1 | T4: 1 | U4: 1 | V4: 1 | W4: 1 | X4: 1 | Y4: 1 | Z4: 1 | AA4: 1
C5: Geralyn Loo | D5: geralyn.loo@warriorlife.net | E5: Aaron Vu | F5: N | G5: 1st Year | H5: 1 | I5: 1 | J5: 1 | K5: 1 | L5: 1 | M5: 1 | N5: 1 | O5: 1 | P5: 1 | Q5: 1 | R5: 0.5 | S5: 1 | T5: 1 | U5: 1 | V5: 1 | W5: 1 | X5: 1 | Y5: 1 | Z5: 1 | AA5: 1
C6: Kashvi Lath | D6: kashvi.lath@warriorlife.net | E6: Aaron Vu | F6: N | G6: 1st Year | H6: 1 | I6: 1 | J6: 1 | K6: 1 | L6: 1 | M6: 1 | N6: 1 | O6: 1 | P6: 1 | Q6: 1 | R6: 1 | S6: 1 | T6: 1 | U6: 1 | V6: 1 | W6: 1 | X6: 1 | Y6: 1 | Z6: 1 | AA6: 1
C7: Gary Zhang | D7: shuhan.zhang@warriorlife.net | E7: Alicia Tang | F7: E | G7: 3rd Year | H7: 2 | I7: 1 | J7: 1 | K7: 0 | L7: 1 | M7: 1 | N7: 0.5 | O7: 1 | P7: 1 | Q7: 1 | R7: 0.5 | S7: 1 | T7: 1 | U7: 1 | V7: 1 | W7: 1 | X7: 1 | Y7: 1 | Z7: 1
C8: Paul Shi | D8: yunbo.shi@warriorlife.net | E8: Alicia Tang | F8: N | G8: 2nd Year | H8: 2 | I8: 1 | J8: 0.5 | K8: 1 | L8: 0.5 | M8: 1 | N8: 1 | O8: 1 | P8: 1 | Q8: 1 | R8: 1 | S8: 1 | T8: 1 | U8: 1 | V8: 0.5 | W8: 1 | X8: 1 | Y8: 1 | Z8: 0
C9: Sofia Yiu | D9: sofia.yiu@warriorlife.net | E9: Alicia Tang | F9: N | G9: 1st Year | H9: 2 | I9: 1 | J9: 1 | K9: 1 | L9: 1 | M9: 1 | N9: 1 | O9: 1 | P9: 1 | Q9: 1 | R9: 1 | S9: 1 | T9: 1 | U9: 1 | V9: 1 | W9: 1 | X9: 1 | Y9: 1 | Z9: 1 | AA9: 1
C10: Sunny Wang | D10: ziqing.wang@warriorlife.net | E10: Alicia Tang | F10: N | G10: 1st Year | H10: 2 | I10: 1 | J10: 1 | K10: 1 | L10: 1 | M10: 1 | N10: 1 | O10: 1 | P10: 1 | Q10: 1 | R10: 1 | S10: 1 | T10: 1 | U10: 1 | V10: 1 | W10: 1 | X10: 1 | Y10: 1 | Z10: 1 | AA10: 1
C11: Arkopriya Aich | D11: arkopriya.aich@warriorlife.net | E11: Alicia Tang | F11: N | G11: 2nd Year | H11: 2 | I11: 1 | J11: 1 | K11: 1 | L11: 1 | M11: 1 | N11: 0 | O11: 1 | P11: 1 | Q11: 1 | R11: 1 | S11: 1 | T11: 0.5 | U11: 1 | V11: 0 | W11: 0 | X11: 0 | Y11: 1 | Z11: 0
C12: Cherrilyn Huynh | D12: t.huynh@warriorlife.net | E12: Arissa Cao | F12: N | G12: 2nd Year | H12: 3 | I12: 1 | J12: 1 | K12: 1 | L12: 1 | M12: 1 | N12: 1 | O12: 0 | P12: 0 | Q12: 0 | R12: 1 | S12: 0 | U12: 1
C13: Madi Nguyen | D13: ct.nguyen@warriorlife.net | E13: Arissa Cao | F13: N | G13: 1st Year | H13: 3 | I13: 1 | J13: 1 | K13: 1 | L13: 1 | M13: 0 | N13: 1 | O13: 1 | P13: 1 | Q13: 1 | R13: 1 | S13: 1 | T13: 1 | U13: 1 | V13: 1 | W13: 1 | X13: 0.5 | Y13: 0.5 | Z13: 1
C14: Keshav Satagopan | D14: sk.satagopan@warriorlife.net | E14: Arissa Cao | F14: E | G14: 2nd Year | H14: 3 | I14: 1 | J14: 1 | K14: 1 | L14: 0.5 | M14: 1 | N14: 1 | O14: 0.5 | P14: 1 | Q14: 1 | R14: 1 | S14: 1 | T14: 1 | U14: 1 | V14: 1 | W14: 1 | X14: 1 | Y14: 1 | Z14: 1 | AA14: 1
C15: Jaden Park | D15: Jaden.park@warriorlife.net | E15: Arissa Cao | F15: E | G15: 3rd Year | H15: 3 | I15: 1 | J15: 1 | K15: 1 | L15: 1 | M15: 1 | N15: 1 | O15: 1 | P15: 1 | Q15: 1 | R15: 1 | S15: 1 | T15: 1 | U15: 1 | V15: 1 | W15: 1 | X15: 1 | Y15: 1 | Z15: 1 | AA15: 1
C16: Sradha Namala | D16: sradha.namala@warriorlife.net | E16: Arissa Cao | F16: N | G16: 1st Year | H16: 3 | I16: 1 | J16: 1 | K16: 1 | L16: 1 | M16: 1 | N16: 1 | O16: 1 | P16: 1 | Q16: 1 | R16: 1 | S16: 1 | T16: 1 | U16: 1 | V16: 1 | W16: 1 | X16: 1 | Y16: 1 | Z16: 1
C17: Franklin Dao | D17: franklin.dao@warriorlife.net | E17: Ayden Wang | F17: E | G17: 3rd Year | H17: 4 | I17: 1 | J17: 1 | K17: 1 | L17: 1 | M17: 1 | N17: 1 | O17: 1 | P17: 1 | Q17: 1 | R17: 1 | S17: 1 | T17: 1 | U17: 1 | V17: 1 | W17: 1 | X17: 1 | Y17: 1 | Z17: 1 | AA17: 1
C18: Samuel Xiao | D18: samuel.xiao@warriorlife.net | E18: Ayden Wang | F18: E | G18: 3rd Year | H18: 4 | I18: 1 | J18: 1 | K18: 1 | L18: 1 | M18: 1 | N18: 1 | O18: 1 | P18: 1 | Q18: 1 | R18: 1 | S18: 1 | T18: 1 | U18: 1 | V18: 1 | W18: 1 | X18: 1 | Y18: 1 | Z18: 1 | AA18: 1
C19: Aubrey Santos | D19: aubrey.santos@warriorlife.net | E19: Ayden Wang | F19: N | G19: 1st Year | H19: 4 | I19: 1 | J19: 0.5 | K19: 1 | L19: 1 | M19: 1 | N19: 1 | O19: 1 | P19: 0.5 | Q19: 1 | R19: 1 | S19: 1 | T19: 1 | U19: 1 | V19: 1 | W19: 1 | X19: 1 | Y19: 1 | Z19: 1
C20: Riyana Baldua | D20: riyana.baldua@warriorlife.net | E20: Ayden Wang | F20: N | G20: 2nd Year | H20: 4 | I20: 1 | J20: 1 | K20: 1 | L20: 0.5 | M20: 1 | N20: 1 | O20: 1 | P20: 1 | Q20: 1 | R20: 1 | S20: 1 | T20: 1 | U20: 1 | V20: 1 | W20: 1 | X20: 1 | Y20: 1 | Z20: 1
C21: Maahir Satwani | D21: maahir.satwani@warriorlife.net | E21: Ayden Wang | F21: N | G21: 1st Year | H21: 4 | I21: 1 | J21: 1 | K21: 1 | L21: 1 | M21: 0.5 | N21: 1 | O21: 1 | P21: 1 | Q21: 1 | R21: 1 | S21: 1 | T21: 1 | U21: 1 | V21: 1 | W21: 1 | X21: 1 | Y21: 1 | Z21: 1
C22: Suvir Maniktala | D22: suvir.maniktala@warriorlife.net | E22: Ayden Wang | F22: N | G22: 2nd Year | H22: 4 | I22: 1 | J22: 1 | K22: 1 | L22: 1 | M22: 0 | N22: 1 | O22: 1 | P22: 1 | Q22: 1 | R22: 1 | S22: 1 | T22: 1 | U22: 1 | V22: 1 | W22: 1 | X22: 1 | Y22: 1 | AA22: 1
C23: Ethan Teh | D23: ethan.teh@warriorlife.net | E23: Chloe Ding | F23: N | G23: 2nd Year | H23: 5 | I23: 1 | J23: 1 | K23: 1 | L23: 1 | M23: 1 | N23: 1 | O23: 1 | P23: 1 | Q23: 1 | R23: 1 | S23: 1 | T23: 1 | U23: 1 | V23: 1 | W23: 1 | X23: 1 | Y23: 1 | Z23: 1
C24: Jason Tang | D24: jason.tang@warriorlife.net | E24: Chloe Ding | F24: N | G24: 2nd Year | H24: 5 | I24: 0.5 | J24: 1 | K24: 1 | L24: 1 | M24: 1 | N24: 1 | O24: 1 | P24: 1 | Q24: 1 | R24: 1 | S24: 1 | T24: 1 | U24: 1 | V24: 1 | W24: 1 | X24: 1 | Y24: 0 | Z24: 1
C25: Gordon Lee | D25: gordon.lee@warriorlife.net | E25: Chloe Ding | F25: N | G25: 1st Year | H25: 5 | I25: 1 | J25: 1 | K25: 1 | L25: 1 | M25: 1 | N25: 1 | O25: 1 | P25: 1 | Q25: 1 | R25: 1 | S25: 1 | T25: 1 | U25: 1 | V25: 1 | W25: 1 | X25: 1 | Y25: 0 | Z25: 1 | AA25: 1
C26: Matthew Zhu | D26: matthew.zhu@warriorlife.net | E26: Chloe Ding | F26: N | G26: 2nd Year | H26: 5 | I26: 1 | J26: 1 | K26: 1 | L26: 1 | M26: 1 | N26: 1 | O26: 1 | P26: 1 | Q26: 1 | R26: 1 | S26: 1 | T26: 1 | U26: 0.5 | V26: 1 | W26: 1 | X26: 1 | Y26: 1 | Z26: 1 | AA26: 1
C27: Isabella Su | D27: isabella.su@warriorlife.net | E27: Chloe Zhong | F27: N | G27: 1st Year | H27: 6 | I27: 1 | J27: 1 | K27: 1 | L27: 1 | M27: 1 | N27: 1 | O27: 1 | P27: 1 | Q27: 1 | R27: 1 | S27: 1 | T27: 1 | U27: 0.5 | V27: 1 | W27: 1 | X27: 1 | Y27: 1 | Z27: 1 | AA27: 1
C28: Ashley Park | D28: ashley.park@warriorlife.net | E28: Chloe Zhong | F28: E | G28: 3rd Year | H28: 6 | I28: 1 | J28: 0.5 | K28: 1 | L28: 1 | M28: 1 | N28: 1 | O28: 1 | P28: 1 | Q28: 1 | R28: 1 | S28: 1 | T28: 1 | U28: 1 | V28: 1 | W28: 1 | X28: 1 | Y28: 1 | Z28: 1 | AA28: 1
C29: Jihoo Lee | D29: jihoo.lee@warriorlife.net | E29: Chloe Zhong | F29: E | G29: 3rd Year | H29: 6 | I29: 1 | J29: 1 | K29: 1 | L29: 1 | M29: 1 | N29: 0.5 | O29: 1 | P29: 1 | Q29: 1 | R29: 1 | S29: 1 | T29: 1 | U29: 0.5 | V29: 1 | W29: 1 | X29: 1 | Y29: 1 | Z29: 1 | AA29: 0
C30: Lucas Wang | D30: lucasj.wang@warriorlife.net | E30: Chloe Zhong | F30: E | G30: 3rd Year | H30: 6 | I30: 1 | J30: 1 | K30: 1 | L30: 1 | M30: 1 | N30: 0.5 | O30: 1 | P30: 1 | Q30: 1 | R30: 1 | S30: 1 | T30: 1 | U30: 1 | V30: 1 | W30: 1 | X30: 1 | Y30: 1 | Z30: 1 | AA30: 0
C31: Kayla Tan | D31: kayla.tan@warriorlife.net | E31: Chloe Zhong | F31: E | G31: 2nd Year | H31: 6 | I31: 1 | J31: 1 | K31: 1 | L31: 1 | M31: 1 | N31: 1 | O31: 1 | P31: 1 | Q31: 1 | R31: 1 | S31: 1 | T31: 1 | U31: 1 | V31: 1 | W31: 1 | X31: 1 | Y31: 1 | Z31: 1 | AA31: 1
C32: Sofia Choo | D32: sofia.choo@warriorlife.net | E32: Chloe Zhong | F32: N | G32: 2nd Year | H32: 6 | I32: 1 | J32: 1 | K32: 1 | L32: 1 | M32: 1 | N32: 0 | O32: 0 | P32: 0 | Q32: 0 | R32: 0 | S32: 0 | T32: 0 | U32: 0 | V32: 0 | W32: 0 | X32: 0 | Y32: 0 | Z32: 0 | AA32: 0
C33: Grace Frieder | D33: grace.frieder@warriorlife.net | E33: Elaine Wang | F33: N | G33: 1st Year | H33: 7 | I33: 1 | J33: 1 | K33: 1 | L33: 1 | M33: 1 | N33: 1 | O33: 1 | P33: 1 | Q33: 1 | R33: 1 | S33: 1 | T33: 1 | U33: 1 | V33: 1 | W33: 1 | X33: 1 | Y33: 1 | Z33: 1 | AA33: 1
C34: Hailey Taylor | D34: hailey.taylor@warriorlife.net | E34: Elaine Wang | F34: N | G34: 1st Year | H34: 7 | I34: 1 | J34: 1 | K34: 1 | L34: 1 | M34: 1 | N34: 1 | O34: 1 | P34: 1 | Q34: 1 | R34: 1 | S34: 1 | T34: 1 | U34: 1 | V34: 1 | W34: 1 | X34: 1 | Y34: 0.5 | Z34: 1 | AA34: 1
C35: Kate Borba | D35: kate.borba@warriorlife.net | E35: Elaine Wang | F35: N | G35: 1st Year | H35: 7 | I35: 1 | J35: 0.5 | K35: 1 | L35: 1 | M35: 1 | N35: 1 | O35: 1 | P35: 1 | Q35: 1 | R35: 1 | S35: 1 | T35: 1 | U35: 1 | V35: 1 | W35: 1 | X35: 1 | Y35: 1 | Z35: 0.5 | AA35: 1
C36: Aditya Poduri | D36: aditya.poduri@warriorlife.net | E36: Elaine Wang | F36: N | G36: 2nd Year | H36: 7 | I36: 1 | J36: 1 | K36: 1 | L36: 1 | M36: 1 | N36: 1 | O36: 1 | P36: 1 | Q36: 0.5 | R36: 1 | S36: 1 | T36: 1 | U36: 1 | V36: 1 | W36: 1 | X36: 1 | Y36: 1 | Z36: 1 | AA36: 1
C37: Jonathan Cheng | D37: jonathan.cheng@warriorlife.net | E37: Elaine Wang | F37: E | G37: 4th Year | H37: 7 | I37: 0 | J37: 0 | K37: 1 | L37: 1 | M37: 1 | N37: 1 | O37: 1 | P37: 1 | Q37: 1 | R37: 1 | S37: 1 | T37: 1 | U37: 1 | V37: 0 | W37: 0 | X37: 0 | Y37: 0 | Z37: 0 | AA37: 0
C38: Michael Deng | D38: michael.deng@warriorlife.net | E38: Elaine Wang | F38: E | G38: 4th Year | H38: 7 | I38: 1 | J38: 1 | K38: 1 | L38: 1 | M38: 1 | N38: 1 | O38: 1 | P38: 1 | Q38: 1 | R38: 1 | S38: 1 | T38: 1 | U38: 1 | V38: 1 | W38: 0 | X38: 0 | Z38: 0
C39: Julia Li | D39: julia.li@warriorlife.net | E39: Elizabeth Huang | F39: E | G39: 2nd Year | H39: 8 | I39: 1 | J39: 1 | K39: 1 | L39: 1 | M39: 1 | N39: 1 | O39: 1 | P39: 1 | Q39: 0.5 | R39: 1 | S39: 1 | T39: 1 | U39: 1 | V39: 1 | W39: 1 | X39: 1 | Y39: 0 | Z39: 1 | AA39: 1
C40: Tiffany Zhang | D40: tiffany.zhang@warriorlife.net | E40: Elizabeth Huang | F40: E | G40: 2nd Year | H40: 8 | I40: 1 | J40: 1 | K40: 1 | L40: 1 | M40: 1 | N40: 1 | O40: 1 | P40: 1 | Q40: 1 | R40: 1 | S40: 1 | T40: 1 | U40: 1 | V40: 1 | W40: 1 | X40: 1 | Y40: 1 | Z40: 1 | AA40: 1
...

Sheet Workshop Attendance 
A1: Timestamp | B1: Email Address | C1: Legal first name | D1: Last name | E1: Workshop Room | F1: What mentee category are you in? (Analytics will track so dont lie) | G1: Who is your mentor? | H1: What's the answer to today's question? | L1: Email | M1: Mentor Name | N1: Nov. or Exp. | O1: Year in DECA | P1: Pod # 0 | Q1: Event | R1: =S1-7 -> 45917 | S1: =T1-7 -> 45924 | T1: =U1-7 -> 45931 | U1: 45938 | V1: 45945 | W1: 45952 | X1: =W1+7 -> 45959 | Y1: =X1+7 -> 45966 | Z1: =Y1+7 -> 45973 | AA1: =Z1+7 -> 45980 | AB1: =AA1+14 -> 45994 | AC1: =AB1+7 -> 46001 | AD1: =AC1+28 -> 46029 | AE1: =AD1+7 -> 46036 | AF1: =AE1+7 -> 46043 | AG1: =AF1+7 -> 46050 | AH1: =AG1+7 -> 46057 | AI1: =AH1+7 -> 46064
A2: 45917.647 | B2: aditya.poduri@warriorlife.net | C2: Aditya | D2: Poduri | E2: G106 | F2: Novice (1st year or 2nd years who haven't placed top 10 (SCDC) or get top 3 (SVCDC)) | G2: Elaine Wang | H2: Make sure not to include too many icons, that can end up becoming a bit redundant. | K2: Amber Chang | L2: ambery.chang@warriorlife.net | M2: Aaron Vu | N2: N | O2: 1st Year | P2: 1 | Q2: BOR | R2: =IF(COUNTIF(B$2:B$149,L2)=0,0,1) -> 1 | S2: =IF(COUNTIF(B$150:B$274,L2)=0,0,1) -> 1 | T2: =IF(COUNTIF(B$275:B$401,L2)=0,0,1) -> 0 | U2: =IFERROR(__xludf.DUMMYFUNCTION("IFERROR(IF(Match(L2,IMPORTRANGE(""https://docs.google.com/spreadsheets/d/1CAXKDiOnZb21bZOY_nacH9xI9AiD-nH8ZZQAwYKkVC0/edit?usp=drivesdk"",""Completed Exams!A1:A135""),0),1), 0)"),0.0) -> 0 | V2: =IF(COUNTIF(B$416:B$535,L2)=0,0,1) -> 1 | W2: 1 | X2: =IF(COUNTIF(B$603:B$725,L2)=0,0,1) -> 1 | Y2: =IF(COUNTIF(B$725:B$844,L2)=0,0,1) -> 1 | Z2: =IF(COUNTIF(B$845:B$969,L2)=0,0,1) -> 1 | AA2: =IF(COUNTIF(B$971:B$1124,L2)=0,0,1) -> 1 | AB2: =IFERROR(__xludf.DUMMYFUNCTION("IFERROR(IF(Match(L2,IMPORTRANGE(""https://docs.google.com/spreadsheets/d/1n1sT_Q_W3mKmn2Yrd8qcNzuRD4zr4DB9gqARnjQ30B4/edit?gid=1918970062#gid=1918970062"",""Form Responses 1!B2:B49""),0),1), 0)"),0.0) -> 0 | AC2: =IF(COUNTIF(B$1145:B$1305,L2)=0,0,1) -> 1 | AD2: 1 | AE2: =IFERROR(__xludf.DUMMYFUNCTION("IFERROR(IF(Match(L2,IMPORTRANGE(""https://docs.google.com/spreadsheets/d/1hvckjcCpxEuDQDPrBMml_I1kBhYyjrgR8qBKC9QGVUc/edit?resourcekey=&gid=230793720#gid=230793720"",""Form Responses 1!B2:B199""),0),1), 0)"),0.0) -> 0 | AF2: =IFERROR(__xludf.DUMMYFUNCTION("IFERROR(IF(Match(L2,IMPORTRANGE(""https://docs.google.com/spreadsheets/d/1UY0hI2S83Fmafa5P-C1LM9yqe4v4qIKTnVy_CzLzRPs/edit?resourcekey=&gid=1583835601#gid=1583835601"",""Form Responses 1!B2:B194""),0),1), 0)"),0.0) -> 0 | AG2: =IFERROR(__xludf.DUMMYFUNCTION("IFERROR(IF(Match(L2,IMPORTRANGE(""https://docs.google.com/spreadsheets/d/1hO4mQ22n6cudUygJ2ss_JeJdm2Ua_7hJl_79lWWEtic/edit?resourcekey=&gid=2087212010#gid=2087212010"",""Form Responses 1!B2:B104""),0),1), 0)"),0.0) -> 0 | AH2: =IFERROR(__xludf.DUMMYFUNCTION("IFERROR(IF(Match(L2,IMPORTRANGE(""https://docs.google.com/spreadsheets/d/1HbfCXhSXbtTODKKY1MOFwJccyhgDKD0J9sO1k5l_6lM/edit?resourcekey=&gid=1616384832#gid=1616384832"",""Form Responses 1!E2:E143""),0),1), 0)"),0.0) -> 0
A3: 45917.647 | B3: armaan.vidhani@warriorlife.net | C3: Armaan | D3: Vidhani | E3: G130 | F3: Novice (1st year or 2nd years who haven't placed top 10 (SCDC) or get top 3 (SVCDC)) | G3: Revathi | H3: I’ve learned not to use that many icons. | K3: Nina Ling | L3: nina.ling@warriorlife.net | M3: Aaron Vu | N3: N | O3: 1st Year | P3: 1 | Q3: BOR | R3: =IF(COUNTIF(B$2:B$149,L3)=0,0,1) -> 1 | S3: =IF(COUNTIF(B$150:B$274,L3)=0,0,1) -> 1 | T3: =IF(COUNTIF(B$275:B$401,L3)=0,0,1) -> 1 | U3: =IFERROR(__xludf.DUMMYFUNCTION("IFERROR(IF(Match(L3,IMPORTRANGE(""https://docs.google.com/spreadsheets/d/1CAXKDiOnZb21bZOY_nacH9xI9AiD-nH8ZZQAwYKkVC0/edit?usp=drivesdk"",""Completed Exams!A1:A135""),0),1), 0)"),0.0) -> 0 | V3: =IF(COUNTIF(B$416:B$535,L3)=0,0,1) -> 1 | W3: =IF(COUNTIF(B$535:B$602,L3)=0,0,1) -> 0 | X3: =IF(COUNTIF(B$603:B$725,L3)=0,0,1) -> 1 | Y3: =IF(COUNTIF(B$725:B$844,L3)=0,0,1) -> 1 | Z3: =IF(COUNTIF(B$845:B$969,L3)=0,0,1) -> 1 | AA3: =IF(COUNTIF(B$971:B$1124,L3)=0,0,1) -> 1 | AB3: 1 | AC3: =IF(COUNTIF(B$1145:B$1305,L3)=0,0,1) -> 1 | AD3: 1 | AE3: =IFERROR(__xludf.DUMMYFUNCTION("IFERROR(IF(Match(L3,IMPORTRANGE(""https://docs.google.com/spreadsheets/d/1hvckjcCpxEuDQDPrBMml_I1kBhYyjrgR8qBKC9QGVUc/edit?resourcekey=&gid=230793720#gid=230793720"",""Form Responses 1!B2:B199""),0),1), 0)"),0.0) -> 0 | AF3: =IFERROR(__xludf.DUMMYFUNCTION("IFERROR(IF(Match(L3,IMPORTRANGE(""https://docs.google.com/spreadsheets/d/1UY0hI2S83Fmafa5P-C1LM9yqe4v4qIKTnVy_CzLzRPs/edit?resourcekey=&gid=1583835601#gid=1583835601"",""Form Responses 1!B2:B194""),0),1), 0)"),0.0) -> 0 | AG3: =IFERROR(__xludf.DUMMYFUNCTION("IFERROR(IF(Match(L3,IMPORTRANGE(""https://docs.google.com/spreadsheets/d/1hO4mQ22n6cudUygJ2ss_JeJdm2Ua_7hJl_79lWWEtic/edit?resourcekey=&gid=2087212010#gid=2087212010"",""Form Responses 1!B2:B104""),0),1), 0)"),0.0) -> 0 | AH3: =IFERROR(__xludf.DUMMYFUNCTION("IFERROR(IF(Match(L3,IMPORTRANGE(""https://docs.google.com/spreadsheets/d/1HbfCXhSXbtTODKKY1MOFwJccyhgDKD0J9sO1k5l_6lM/edit?resourcekey=&gid=1616384832#gid=1616384832"",""Form Responses 1!E2:E143""),0),1), 0)"),0.0) -> 0
A4: 45917.647 | B4: tan.pham@warriorlife.net | C4: Tan | D4: Pham | E4: G130 | F4: Experienced (2nd years who have placed top 10 (SCDC) or get top 3 (SVCDC) or 3rd and 4th years) | G4: Sophia White | H4: Templates are your best friend. | K4: Elize Kaldani | L4: elize.kaldani@warriorlife.net | M4: Aaron Vu | N4: N | O4: 1st Year | P4: 1 | Q4: BOR | R4: =IF(COUNTIF(B$2:B$149,L4)=0,0,1) -> 1 | S4: =IF(COUNTIF(B$150:B$274,L4)=0,0,1) -> 1 | T4: =IF(COUNTIF(B$275:B$401,L4)=0,0,1) -> 1 | U4: =IFERROR(__xludf.DUMMYFUNCTION("IFERROR(IF(Match(L4,IMPORTRANGE(""https://docs.google.com/spreadsheets/d/1CAXKDiOnZb21bZOY_nacH9xI9AiD-nH8ZZQAwYKkVC0/edit?usp=drivesdk"",""Completed Exams!A1:A135""),0),1), 0)"),0.0) -> 0 | V4: =IF(COUNTIF(B$416:B$535,L4)=0,0,1) -> 1 | W4: 1 | X4: =IF(COUNTIF(B$603:B$725,L4)=0,0,1) -> 0 | Y4: =IF(COUNTIF(B$725:B$844,L4)=0,0,1) -> 1 | Z4: =IF(COUNTIF(B$845:B$969,L4)=0,0,1) -> 1 | AA4: =IF(COUNTIF(B$971:B$1124,L4)=0,0,1) -> 1 | AB4: =IFERROR(__xludf.DUMMYFUNCTION("IFERROR(IF(Match(L4,IMPORTRANGE(""https://docs.google.com/spreadsheets/d/1n1sT_Q_W3mKmn2Yrd8qcNzuRD4zr4DB9gqARnjQ30B4/edit?gid=1918970062#gid=1918970062"",""Form Responses 1!B2:B49""),0),1), 0)"),0.0) -> 0 | AC4: =IF(COUNTIF(B$1145:B$1305,L4)=0,0,1) -> 1 | AD4: 1 | AE4: =IFERROR(__xludf.DUMMYFUNCTION("IFERROR(IF(Match(L4,IMPORTRANGE(""https://docs.google.com/spreadsheets/d/1hvckjcCpxEuDQDPrBMml_I1kBhYyjrgR8qBKC9QGVUc/edit?resourcekey=&gid=230793720#gid=230793720"",""Form Responses 1!B2:B199""),0),1), 0)"),0.0) -> 0 | AF4: =IFERROR(__xludf.DUMMYFUNCTION("IFERROR(IF(Match(L4,IMPORTRANGE(""https://docs.google.com/spreadsheets/d/1UY0hI2S83Fmafa5P-C1LM9yqe4v4qIKTnVy_CzLzRPs/edit?resourcekey=&gid=1583835601#gid=1583835601"",""Form Responses 1!B2:B194""),0),1), 0)"),0.0) -> 0 | AG4: =IFERROR(__xludf.DUMMYFUNCTION("IFERROR(IF(Match(L4,IMPORTRANGE(""https://docs.google.com/spreadsheets/d/1hO4mQ22n6cudUygJ2ss_JeJdm2Ua_7hJl_79lWWEtic/edit?resourcekey=&gid=2087212010#gid=2087212010"",""Form Responses 1!B2:B104""),0),1), 0)"),0.0) -> 0 | AH4: =IFERROR(__xludf.DUMMYFUNCTION("IFERROR(IF(Match(L4,IMPORTRANGE(""https://docs.google.com/spreadsheets/d/1HbfCXhSXbtTODKKY1MOFwJccyhgDKD0J9sO1k5l_6lM/edit?resourcekey=&gid=1616384832#gid=1616384832"",""Form Responses 1!E2:E143""),0),1), 0)"),0.0) -> 0
A5: 45917.647 | B5: nathaniel.kommu@warriorlife.net | C5: Nathaniel | D5: Kommu | E5: G130 | F5: Novice (1st year or 2nd years who haven't placed top 10 (SCDC) or top 3 (SVCDC)) | G5: Emily Tang | H5: Split information into multiple parts | K5: Geralyn Loo | L5: geralyn.loo@warriorlife.net | M5: Aaron Vu | N5: N | O5: 1st Year | P5: 1 | Q5: BMOR | R5: =IF(COUNTIF(B$2:B$149,L5)=0,0,1) -> 1 | S5: =IF(COUNTIF(B$150:B$274,L5)=0,0,1) -> 1 | T5: =IF(COUNTIF(B$275:B$401,L5)=0,0,1) -> 1 | U5: =IFERROR(__xludf.DUMMYFUNCTION("IFERROR(IF(Match(L5,IMPORTRANGE(""https://docs.google.com/spreadsheets/d/1CAXKDiOnZb21bZOY_nacH9xI9AiD-nH8ZZQAwYKkVC0/edit?usp=drivesdk"",""Completed Exams!A1:A135""),0),1), 0)"),0.0) -> 0 | V5: =IF(COUNTIF(B$416:B$535,L5)=0,0,1) -> 1 | W5: =IF(COUNTIF(B$535:B$602,L5)=0,0,1) -> 1 | X5: =IF(COUNTIF(B$603:B$725,L5)=0,0,1) -> 1 | Y5: =IF(COUNTIF(B$725:B$844,L5)=0,0,1) -> 1 | Z5: =IF(COUNTIF(B$845:B$969,L5)=0,0,1) -> 1 | AA5: =IF(COUNTIF(B$971:B$1124,L5)=0,0,1) -> 1 | AB5: =IFERROR(__xludf.DUMMYFUNCTION("IFERROR(IF(Match(L5,IMPORTRANGE(""https://docs.google.com/spreadsheets/d/1n1sT_Q_W3mKmn2Yrd8qcNzuRD4zr4DB9gqARnjQ30B4/edit?gid=1918970062#gid=1918970062"",""Form Responses 1!B2:B49""),0),1), 0)"),0.0) -> 0 | AC5: =IF(COUNTIF(B$1145:B$1305,L5)=0,0,1) -> 1 | AD5: 1 | AE5: =IFERROR(__xludf.DUMMYFUNCTION("IFERROR(IF(Match(L5,IMPORTRANGE(""https://docs.google.com/spreadsheets/d/1hvckjcCpxEuDQDPrBMml_I1kBhYyjrgR8qBKC9QGVUc/edit?resourcekey=&gid=230793720#gid=230793720"",""Form Responses 1!B2:B199""),0),1), 0)"),0.0) -> 0 | AF5: =IFERROR(__xludf.DUMMYFUNCTION("IFERROR(IF(Match(L5,IMPORTRANGE(""https://docs.google.com/spreadsheets/d/1UY0hI2S83Fmafa5P-C1LM9yqe4v4qIKTnVy_CzLzRPs/edit?resourcekey=&gid=1583835601#gid=1583835601"",""Form Responses 1!B2:B194""),0),1), 0)"),0.0) -> 0 | AG5: =IFERROR(__xludf.DUMMYFUNCTION("IFERROR(IF(Match(L5,IMPORTRANGE(""https://docs.google.com/spreadsheets/d/1hO4mQ22n6cudUygJ2ss_JeJdm2Ua_7hJl_79lWWEtic/edit?resourcekey=&gid=2087212010#gid=2087212010"",""Form Responses 1!B2:B104""),0),1), 0)"),0.0) -> 0 | AH5: =IFERROR(__xludf.DUMMYFUNCTION("IFERROR(IF(Match(L5,IMPORTRANGE(""https://docs.google.com/spreadsheets/d/1HbfCXhSXbtTODKKY1MOFwJccyhgDKD0J9sO1k5l_6lM/edit?resourcekey=&gid=1616384832#gid=1616384832"",""Form Responses 1!E2:E143""),0),1), 0)"),0.0) -> 0
A6: 45917.647 | B6: allen.tu@warriorlife.net | C6: Allen | D6: Tu | E6: G130 | F6: Experienced (2nd years who have placed top 10 (SCDC) or top 3 (SVCDC) or 3rd and 4th years) | G6: Suneri | H6: Don’t use a lot of icons | K6: Kashvi Lath | L6: kashvi.lath@warriorlife.net | M6: Aaron Vu | N6: N | O6: 1st Year | P6: 1 | Q6: BOR | R6: =IF(COUNTIF(B$2:B$149,L6)=0,0,1) -> 1 | S6: =IF(COUNTIF(B$150:B$274,L6)=0,0,1) -> 1 | T6: =IF(COUNTIF(B$275:B$401,L6)=0,0,1) -> 1 | U6: =IFERROR(__xludf.DUMMYFUNCTION("IFERROR(IF(Match(L6,IMPORTRANGE(""https://docs.google.com/spreadsheets/d/1CAXKDiOnZb21bZOY_nacH9xI9AiD-nH8ZZQAwYKkVC0/edit?usp=drivesdk"",""Completed Exams!A1:A135""),0),1), 0)"),0.0) -> 0 | V6: =IF(COUNTIF(B$416:B$535,L6)=0,0,1) -> 1 | W6: =IF(COUNTIF(B$535:B$602,L6)=0,0,1) -> 1 | X6: =IF(COUNTIF(B$603:B$725,L6)=0,0,1) -> 1 | Y6: =IF(COUNTIF(B$725:B$844,L6)=0,0,1) -> 1 | Z6: =IF(COUNTIF(B$845:B$969,L6)=0,0,1) -> 1 | AA6: =IF(COUNTIF(B$971:B$1124,L6)=0,0,1) -> 1 | AB6: 1 | AC6: =IF(COUNTIF(B$1145:B$1305,L6)=0,0,1) -> 1 | AD6: 1 | AE6: =IFERROR(__xludf.DUMMYFUNCTION("IFERROR(IF(Match(L6,IMPORTRANGE(""https://docs.google.com/spreadsheets/d/1hvckjcCpxEuDQDPrBMml_I1kBhYyjrgR8qBKC9QGVUc/edit?resourcekey=&gid=230793720#gid=230793720"",""Form Responses 1!B2:B199""),0),1), 0)"),0.0) -> 0 | AF6: =IFERROR(__xludf.DUMMYFUNCTION("IFERROR(IF(Match(L6,IMPORTRANGE(""https://docs.google.com/spreadsheets/d/1UY0hI2S83Fmafa5P-C1LM9yqe4v4qIKTnVy_CzLzRPs/edit?resourcekey=&gid=1583835601#gid=1583835601"",""Form Responses 1!B2:B194""),0),1), 0)"),0.0) -> 0 | AG6: =IFERROR(__xludf.DUMMYFUNCTION("IFERROR(IF(Match(L6,IMPORTRANGE(""https://docs.google.com/spreadsheets/d/1hO4mQ22n6cudUygJ2ss_JeJdm2Ua_7hJl_79lWWEtic/edit?resourcekey=&gid=2087212010#gid=2087212010"",""Form Responses 1!B2:B104""),0),1), 0)"),0.0) -> 0 | AH6: =IFERROR(__xludf.DUMMYFUNCTION("IFERROR(IF(Match(L6,IMPORTRANGE(""https://docs.google.com/spreadsheets/d/1HbfCXhSXbtTODKKY1MOFwJccyhgDKD0J9sO1k5l_6lM/edit?resourcekey=&gid=1616384832#gid=1616384832"",""Form Responses 1!E2:E143""),0),1), 0)"),0.0) -> 0
A7: 45917.647 | B7: kayla.tan@warriorlife.net | C7: Kayla | D7: Tan | E7: G130 | F7: Experienced (2nd years who have placed top 10 (SCDC) or top 3 (SVCDC) or 3rd and 4th years) | G7: Jayden | H7: Less icons are better | K7: Gary Zhang | L7: shuhan.zhang@warriorlife.net | M7: Alicia Tang | N7: E | O7: 3rd Year | P7: 2 | Q7: ESB | R7: =IF(COUNTIF(B$2:B$149,L7)=0,0,1) -> 1 | S7: =IF(COUNTIF(B$150:B$274,L7)=0,0,1) -> 0 | T7: =IF(COUNTIF(B$275:B$401,L7)=0,0,1) -> 0 | U7: 1 | V7: =IF(COUNTIF(B$416:B$535,L7)=0,0,1) -> 0 | W7: =IF(COUNTIF(B$535:B$602,L7)=0,0,1) -> 1 | X7: =IF(COUNTIF(B$603:B$725,L7)=0,0,1) -> 0 | Y7: =IF(COUNTIF(B$725:B$844,L7)=0,0,1) -> 0 | Z7: =IF(COUNTIF(B$845:B$969,L7)=0,0,1) -> 0 | AA7: 0.5 | AB7: =IFERROR(__xludf.DUMMYFUNCTION("IFERROR(IF(Match(L7,IMPORTRANGE(""https://docs.google.com/spreadsheets/d/1n1sT_Q_W3mKmn2Yrd8qcNzuRD4zr4DB9gqARnjQ30B4/edit?gid=1918970062#gid=1918970062"",""Form Responses 1!B2:B49""),0),1), 0)"),0.0) -> 0 | AC7: =IF(COUNTIF(B$1145:B$1305,L7)=0,0,1) -> 1 | AD7: 0 | AE7: =IFERROR(__xludf.DUMMYFUNCTION("IFERROR(IF(Match(L7,IMPORTRANGE(""https://docs.google.com/spreadsheets/d/1hvckjcCpxEuDQDPrBMml_I1kBhYyjrgR8qBKC9QGVUc/edit?resourcekey=&gid=230793720#gid=230793720"",""Form Responses 1!B2:B199""),0),1), 0)"),0.0) -> 0 | AF7: =IFERROR(__xludf.DUMMYFUNCTION("IFERROR(IF(Match(L7,IMPORTRANGE(""https://docs.google.com/spreadsheets/d/1UY0hI2S83Fmafa5P-C1LM9yqe4v4qIKTnVy_CzLzRPs/edit?resourcekey=&gid=1583835601#gid=1583835601"",""Form Responses 1!B2:B194""),0),1), 0)"),0.0) -> 0 | AG7: =IFERROR(__xludf.DUMMYFUNCTION("IFERROR(IF(Match(L7,IMPORTRANGE(""https://docs.google.com/spreadsheets/d/1hO4mQ22n6cudUygJ2ss_JeJdm2Ua_7hJl_79lWWEtic/edit?resourcekey=&gid=2087212010#gid=2087212010"",""Form Responses 1!B2:B104""),0),1), 0)"),0.0) -> 0 | AH7: 0.5
A8: 45917.647 | B8: marisol.chou@warriorlife.net | C8: Marisol | D8: Chou | E8: G109 | F8: Novice (1st year or 2nd years who haven't placed top 10 (SCDC) or top 3 (SVCDC)) | G8: Riday Appannagari | H8: pick nice colors for the design! | K8: Paul Shi | L8: yunbo.shi@warriorlife.net | M8: Alicia Tang | N8: N | O8: 2nd Year | P8: 2 | Q8: ESB | R8: =IF(COUNTIF(B$2:B$149,L8)=0,0,1) -> 0 | S8: =IF(COUNTIF(B$150:B$274,L8)=0,0,1) -> 1 | T8: =IF(COUNTIF(B$275:B$401,L8)=0,0,1) -> 1 | U8: =IFERROR(__xludf.DUMMYFUNCTION("IFERROR(IF(Match(L8,IMPORTRANGE(""https://docs.google.com/spreadsheets/d/1CAXKDiOnZb21bZOY_nacH9xI9AiD-nH8ZZQAwYKkVC0/edit?usp=drivesdk"",""Completed Exams!A1:A135""),0),1), 0)"),0.0) -> 0 | V8: =IF(COUNTIF(B$416:B$535,L8)=0,0,1) -> 1 | W8: =IF(COUNTIF(B$535:B$602,L8)=0,0,1) -> 1 | X8: =IF(COUNTIF(B$603:B$725,L8)=0,0,1) -> 1 | Y8: =IF(COUNTIF(B$725:B$844,L8)=0,0,1) -> 1 | Z8: =IF(COUNTIF(B$845:B$969,L8)=0,0,1) -> 1 | AA8: =IF(COUNTIF(B$971:B$1124,L8)=0,0,1) -> 1 | AB8: =IFERROR(__xludf.DUMMYFUNCTION("IFERROR(IF(Match(L8,IMPORTRANGE(""https://docs.google.com/spreadsheets/d/1n1sT_Q_W3mKmn2Yrd8qcNzuRD4zr4DB9gqARnjQ30B4/edit?gid=1918970062#gid=1918970062"",""Form Responses 1!B2:B49""),0),1), 0)"),0.0) -> 0 | AC8: =IF(COUNTIF(B$1145:B$1305,L8)=0,0,1) -> 1 | AD8: 1 | AE8: 0.5 | AF8: =IFERROR(__xludf.DUMMYFUNCTION("IFERROR(IF(Match(L8,IMPORTRANGE(""https://docs.google.com/spreadsheets/d/1UY0hI2S83Fmafa5P-C1LM9yqe4v4qIKTnVy_CzLzRPs/edit?resourcekey=&gid=1583835601#gid=1583835601"",""Form Responses 1!B2:B194""),0),1), 0)"),0.0) -> 0 | AG8: =IFERROR(__xludf.DUMMYFUNCTION("IFERROR(IF(Match(L8,IMPORTRANGE(""https://docs.google.com/spreadsheets/d/1hO4mQ22n6cudUygJ2ss_JeJdm2Ua_7hJl_79lWWEtic/edit?resourcekey=&gid=2087212010#gid=2087212010"",""Form Responses 1!B2:B104""),0),1), 0)"),0.0) -> 0 | AH8: =IFERROR(__xludf.DUMMYFUNCTION("IFERROR(IF(Match(L8,IMPORTRANGE(""https://docs.google.com/spreadsheets/d/1HbfCXhSXbtTODKKY1MOFwJccyhgDKD0J9sO1k5l_6lM/edit?resourcekey=&gid=1616384832#gid=1616384832"",""Form Responses 1!E2:E143""),0),1), 0)"),0.0) -> 0
A9: 45917.647 | B9: zayd.bashadi@warriorlife.net | C9: Zayd | D9: Bashadi | E9: G130 | F9: Novice (1st year or 2nd years who haven't placed top 10 (SCDC) or top 3 (SVCDC)) | G9: Jayden | H9: Templets are good | K9: Sofia Yiu | L9: sofia.yiu@warriorlife.net | M9: Alicia Tang | N9: N | O9: 1st Year | P9: 2 | Q9: SEOR | R9: =IF(COUNTIF(B$2:B$149,L9)=0,0,1) -> 1 | S9: =IF(COUNTIF(B$150:B$274,L9)=0,0,1) -> 1 | T9: =IF(COUNTIF(B$275:B$401,L9)=0,0,1) -> 1 | U9: =IFERROR(__xludf.DUMMYFUNCTION("IFERROR(IF(Match(L9,IMPORTRANGE(""https://docs.google.com/spreadsheets/d/1CAXKDiOnZb21bZOY_nacH9xI9AiD-nH8ZZQAwYKkVC0/edit?usp=drivesdk"",""Completed Exams!A1:A135""),0),1), 0)"),0.0) -> 0 | V9: =IF(COUNTIF(B$416:B$535,L9)=0,0,1) -> 1 | W9: 0.5 | X9: =IF(COUNTIF(B$603:B$725,L9)=0,0,1) -> 1 | Y9: =IF(COUNTIF(B$725:B$844,L9)=0,0,1) -> 1 | Z9: =IF(COUNTIF(B$845:B$969,L9)=0,0,1) -> 1 | AA9: =IF(COUNTIF(B$971:B$1124,L9)=0,0,1) -> 1 | AB9: 1 | AC9: =IF(COUNTIF(B$1145:B$1305,L9)=0,0,1) -> 1 | AD9: 1 | AE9: =IFERROR(__xludf.DUMMYFUNCTION("IFERROR(IF(Match(L9,IMPORTRANGE(""https://docs.google.com/spreadsheets/d/1hvckjcCpxEuDQDPrBMml_I1kBhYyjrgR8qBKC9QGVUc/edit?resourcekey=&gid=230793720#gid=230793720"",""Form Responses 1!B2:B199""),0),1), 0)"),0.0) -> 0 | AF9: =IFERROR(__xludf.DUMMYFUNCTION("IFERROR(IF(Match(L9,IMPORTRANGE(""https://docs.google.com/spreadsheets/d/1UY0hI2S83Fmafa5P-C1LM9yqe4v4qIKTnVy_CzLzRPs/edit?resourcekey=&gid=1583835601#gid=1583835601"",""Form Responses 1!B2:B194""),0),1), 0)"),0.0) -> 0 | AG9: =IFERROR(__xludf.DUMMYFUNCTION("IFERROR(IF(Match(L9,IMPORTRANGE(""https://docs.google.com/spreadsheets/d/1hO4mQ22n6cudUygJ2ss_JeJdm2Ua_7hJl_79lWWEtic/edit?resourcekey=&gid=2087212010#gid=2087212010"",""Form Responses 1!B2:B104""),0),1), 0)"),0.0) -> 0 | AH9: =IFERROR(__xludf.DUMMYFUNCTION("IFERROR(IF(Match(L9,IMPORTRANGE(""https://docs.google.com/spreadsheets/d/1HbfCXhSXbtTODKKY1MOFwJccyhgDKD0J9sO1k5l_6lM/edit?resourcekey=&gid=1616384832#gid=1616384832"",""Form Responses 1!E2:E143""),0),1), 0)"),0.0) -> 0
A10: 45917.647 | B10: tiara.wang@warriorlife.net | C10: Tiara | D10: Wang | E10: G130 | F10: Experienced (2nd years who have placed top 10 (SCDC) or top 3 (SVCDC) or 3rd and 4th years) | G10: Suneri | H10: I learned about the whiteboard option on canva | K10: Sunny Wang | L10: ziqing.wang@warriorlife.net | M10: Alicia Tang | N10: N | O10: 1st Year | P10: 2 | Q10: SEOR | R10: =IF(COUNTIF(B$2:B$149,L10)=0,0,1) -> 1 | S10: =IF(COUNTIF(B$150:B$274,L10)=0,0,1) -> 1 | T10: =IF(COUNTIF(B$275:B$401,L10)=0,0,1) -> 1 | U10: =IFERROR(__xludf.DUMMYFUNCTION("IFERROR(IF(Match(L10,IMPORTRANGE(""https://docs.google.com/spreadsheets/d/1CAXKDiOnZb21bZOY_nacH9xI9AiD-nH8ZZQAwYKkVC0/edit?usp=drivesdk"",""Completed Exams!A1:A135""),0),1), 0)"),0.0) -> 0 | V10: =IF(COUNTIF(B$416:B$535,L10)=0,0,1) -> 1 | W10: 0.5 | X10: =IF(COUNTIF(B$603:B$725,L10)=0,0,1) -> 1 | Y10: =IF(COUNTIF(B$725:B$844,L10)=0,0,1) -> 1 | Z10: =IF(COUNTIF(B$845:B$969,L10)=0,0,1) -> 1 | AA10: =IF(COUNTIF(B$971:B$1124,L10)=0,0,1) -> 1 | AB10: =IFERROR(__xludf.DUMMYFUNCTION("IFERROR(IF(Match(L10,IMPORTRANGE(""https://docs.google.com/spreadsheets/d/1n1sT_Q_W3mKmn2Yrd8qcNzuRD4zr4DB9gqARnjQ30B4/edit?gid=1918970062#gid=1918970062"",""Form Responses 1!B2:B49""),0),1), 0)"),0.0) -> 0 | AC10: =IF(COUNTIF(B$1145:B$1305,L10)=0,0,1) -> 1 | AD10: 1 | AE10: =IFERROR(__xludf.DUMMYFUNCTION("IFERROR(IF(Match(L10,IMPORTRANGE(""https://docs.google.com/spreadsheets/d/1hvckjcCpxEuDQDPrBMml_I1kBhYyjrgR8qBKC9QGVUc/edit?resourcekey=&gid=230793720#gid=230793720"",""Form Responses 1!B2:B199""),0),1), 0)"),0.0) -> 0 | AF10: =IFERROR(__xludf.DUMMYFUNCTION("IFERROR(IF(Match(L10,IMPORTRANGE(""https://docs.google.com/spreadsheets/d/1UY0hI2S83Fmafa5P-C1LM9yqe4v4qIKTnVy_CzLzRPs/edit?resourcekey=&gid=1583835601#gid=1583835601"",""Form Responses 1!B2:B194""),0),1), 0)"),0.0) -> 0 | AG10: =IFERROR(__xludf.DUMMYFUNCTION("IFERROR(IF(Match(L10,IMPORTRANGE(""https://docs.google.com/spreadsheets/d/1hO4mQ22n6cudUygJ2ss_JeJdm2Ua_7hJl_79lWWEtic/edit?resourcekey=&gid=2087212010#gid=2087212010"",""Form Responses 1!B2:B104""),0),1), 0)"),0.0) -> 0 | AH10: =IFERROR(__xludf.DUMMYFUNCTION("IFERROR(IF(Match(L10,IMPORTRANGE(""https://docs.google.com/spreadsheets/d/1HbfCXhSXbtTODKKY1MOFwJccyhgDKD0J9sO1k5l_6lM/edit?resourcekey=&gid=1616384832#gid=1616384832"",""Form Responses 1!E2:E143""),0),1), 0)"),0.0) -> 0
A11: 45917.647 | B11: christine.choo@warriorlife.net | C11: Christine | D11: Choo | E11: G130 | F11: Novice (1st year or 2nd years who haven't placed top 10 (SCDC) or top 3 (SVCDC)) | G11: Riday | H11: Canva whiteboard is really useful for planning. | K11: Arkopriya Aich | L11: arkopriya.aich@warriorlife.net | M11: Alicia Tang | N11: N | O11: 2nd Year | P11: 2 | Q11: PSE | R11: 0.5 | S11: 0.5 | T11: =IF(COUNTIF(B$275:B$401,L11)=0,0,1) -> 1 | U11: =IFERROR(__xludf.DUMMYFUNCTION("IFERROR(IF(Match(L11,IMPORTRANGE(""https://docs.google.com/spreadsheets/d/1CAXKDiOnZb21bZOY_nacH9xI9AiD-nH8ZZQAwYKkVC0/edit?usp=drivesdk"",""Completed Exams!A1:A135""),0),1), 0)"),0.0) -> 0 | V11: =IF(COUNTIF(B$416:B$535,L11)=0,0,1) -> 1 | W11: =IF(COUNTIF(B$535:B$602,L11)=0,0,1) -> 0 | X11: =IF(COUNTIF(B$603:B$725,L11)=0,0,1) -> 1 | Y11: =IF(COUNTIF(B$725:B$844,L11)=0,0,1) -> 1 | Z11: =IF(COUNTIF(B$845:B$969,L11)=0,0,1) -> 1 | AA11: =IF(COUNTIF(B$971:B$1124,L11)=0,0,1) -> 1 | AB11: =IFERROR(__xludf.DUMMYFUNCTION("IFERROR(IF(Match(L11,IMPORTRANGE(""https://docs.google.com/spreadsheets/d/1n1sT_Q_W3mKmn2Yrd8qcNzuRD4zr4DB9gqARnjQ30B4/edit?gid=1918970062#gid=1918970062"",""Form Responses 1!B2:B49""),0),1), 0)"),0.0) -> 0 | AC11: =IF(COUNTIF(B$1145:B$1305,L11)=0,0,1) -> 1 | AD11: 0.5 | AE11: =IFERROR(__xludf.DUMMYFUNCTION("IFERROR(IF(Match(L11,IMPORTRANGE(""https://docs.google.com/spreadsheets/d/1hvckjcCpxEuDQDPrBMml_I1kBhYyjrgR8qBKC9QGVUc/edit?resourcekey=&gid=230793720#gid=230793720"",""Form Responses 1!B2:B199""),0),1), 0)"),0.0) -> 0 | AF11: =IFERROR(__xludf.DUMMYFUNCTION("IFERROR(IF(Match(L11,IMPORTRANGE(""https://docs.google.com/spreadsheets/d/1UY0hI2S83Fmafa5P-C1LM9yqe4v4qIKTnVy_CzLzRPs/edit?resourcekey=&gid=1583835601#gid=1583835601"",""Form Responses 1!B2:B194""),0),1), 0)"),0.0) -> 0 | AG11: =IFERROR(__xludf.DUMMYFUNCTION("IFERROR(IF(Match(L11,IMPORTRANGE(""https://docs.google.com/spreadsheets/d/1hO4mQ22n6cudUygJ2ss_JeJdm2Ua_7hJl_79lWWEtic/edit?resourcekey=&gid=2087212010#gid=2087212010"",""Form Responses 1!B2:B104""),0),1), 0)"),0.0) -> 0 | AH11: =IFERROR(__xludf.DUMMYFUNCTION("IFERROR(IF(Match(L11,IMPORTRANGE(""https://docs.google.com/spreadsheets/d/1HbfCXhSXbtTODKKY1MOFwJccyhgDKD0J9sO1k5l_6lM/edit?resourcekey=&gid=1616384832#gid=1616384832"",""Form Responses 1!E2:E143""),0),1), 0)"),0.0) -> 0
A12: 45917.647 | B12: lincolnjacob.tran@warriorlife.net | C12: Lincoln | D12: Tran | E12: G130 | F12: Novice (1st year or 2nd years who haven't placed top 10 (SCDC) or top 3 (SVCDC)) | G12: Xiaowei Zhang | H12: I learned to use the whiteboard on canva to see how we can scale our franchise business plan | K12: Cherrilyn Huynh | L12: t.huynh@warriorlife.net | M12: Arissa Cao | N12: N | O12: 2nd Year | P12: 3 | Q12: BMOR | R12: =IF(COUNTIF(B$2:B$149,L12)=0,0,1) -> 1 | S12: =IF(COUNTIF(B$150:B$274,L12)=0,0,1) -> 1 | T12: =IF(COUNTIF(B$275:B$401,L12)=0,0,1) -> 1 | U12: =IFERROR(__xludf.DUMMYFUNCTION("IFERROR(IF(Match(L12,IMPORTRANGE(""https://docs.google.com/spreadsheets/d/1CAXKDiOnZb21bZOY_nacH9xI9AiD-nH8ZZQAwYKkVC0/edit?usp=drivesdk"",""Completed Exams!A1:A135""),0),1), 0)"),0.0) -> 0 | V12: =IF(COUNTIF(B$416:B$535,L12)=0,0,1) -> 0 | W12: =IF(COUNTIF(B$535:B$602,L12)=0,0,1) -> 1 | X12: =IF(COUNTIF(B$603:B$725,L12)=0,0,1) -> 0 | Y12: =IF(COUNTIF(B$725:B$844,L12)=0,0,1) -> 0 | Z12: =IF(COUNTIF(B$845:B$969,L12)=0,0,1) -> 0 | AA12: =IF(COUNTIF(B$971:B$1124,L12)=0,0,1) -> 0 | AB12: =IFERROR(__xludf.DUMMYFUNCTION("IFERROR(IF(Match(L12,IMPORTRANGE(""https://docs.google.com/spreadsheets/d/1n1sT_Q_W3mKmn2Yrd8qcNzuRD4zr4DB9gqARnjQ30B4/edit?gid=1918970062#gid=1918970062"",""Form Responses 1!B2:B49""),0),1), 0)"),0.0) -> 0 | AC12: =IF(COUNTIF(B$1145:B$1305,L12)=0,0,1) -> 0 | AD12: 0 | AE12: =IFERROR(__xludf.DUMMYFUNCTION("IFERROR(IF(Match(L12,IMPORTRANGE(""https://docs.google.com/spreadsheets/d/1hvckjcCpxEuDQDPrBMml_I1kBhYyjrgR8qBKC9QGVUc/edit?resourcekey=&gid=230793720#gid=230793720"",""Form Responses 1!B2:B199""),0),1), 0)"),0.0) -> 0 | AF12: =IFERROR(__xludf.DUMMYFUNCTION("IFERROR(IF(Match(L12,IMPORTRANGE(""https://docs.google.com/spreadsheets/d/1UY0hI2S83Fmafa5P-C1LM9yqe4v4qIKTnVy_CzLzRPs/edit?resourcekey=&gid=1583835601#gid=1583835601"",""Form Responses 1!B2:B194""),0),1), 0)"),0.0) -> 0 | AG12: =IFERROR(__xludf.DUMMYFUNCTION("IFERROR(IF(Match(L12,IMPORTRANGE(""https://docs.google.com/spreadsheets/d/1hO4mQ22n6cudUygJ2ss_JeJdm2Ua_7hJl_79lWWEtic/edit?resourcekey=&gid=2087212010#gid=2087212010"",""Form Responses 1!B2:B104""),0),1), 0)"),0.0) -> 0 | AH12: =IFERROR(__xludf.DUMMYFUNCTION("IFERROR(IF(Match(L12,IMPORTRANGE(""https://docs.google.com/spreadsheets/d/1HbfCXhSXbtTODKKY1MOFwJccyhgDKD0J9sO1k5l_6lM/edit?resourcekey=&gid=1616384832#gid=1616384832"",""Form Responses 1!E2:E143""),0),1), 0)"),0.0) -> 0
A13: 45917.647 | B13: haochien.wang@warriorlife.net | C13: hao-chien | D13: wang | E13: G130 | F13: Novice (1st year or 2nd years who haven't placed top 10 (SCDC) or top 3 (SVCDC)) | G13: xiaowei zhang | H13: we learned about writttens and see how we can scale our franchise plan. | K13: Madi Nguyen | L13: ct.nguyen@warriorlife.net | M13: Arissa Cao | N13: N | O13: 1st Year | P13: 3 | Q13: BMOR | R13: =IF(COUNTIF(B$2:B$149,L13)=0,0,1) -> 1 | S13: =IF(COUNTIF(B$150:B$274,L13)=0,0,1) -> 1 | T13: =IF(COUNTIF(B$275:B$401,L13)=0,0,1) -> 1 | U13: =IFERROR(__xludf.DUMMYFUNCTION("IFERROR(IF(Match(L13,IMPORTRANGE(""https://docs.google.com/spreadsheets/d/1CAXKDiOnZb21bZOY_nacH9xI9AiD-nH8ZZQAwYKkVC0/edit?usp=drivesdk"",""Completed Exams!A1:A135""),0),1), 0)"),0.0) -> 0 | V13: =IF(COUNTIF(B$416:B$535,L13)=0,0,1) -> 0 | W13: =IF(COUNTIF(B$535:B$602,L13)=0,0,1) -> 1 | X13: =IF(COUNTIF(B$603:B$725,L13)=0,0,1) -> 1 | Y13: =IF(COUNTIF(B$725:B$844,L13)=0,0,1) -> 1 | Z13: =IF(COUNTIF(B$845:B$969,L13)=0,0,1) -> 1 | AA13: =IF(COUNTIF(B$971:B$1124,L13)=0,0,1) -> 1 | AB13: =IFERROR(__xludf.DUMMYFUNCTION("IFERROR(IF(Match(L13,IMPORTRANGE(""https://docs.google.com/spreadsheets/d/1n1sT_Q_W3mKmn2Yrd8qcNzuRD4zr4DB9gqARnjQ30B4/edit?gid=1918970062#gid=1918970062"",""Form Responses 1!B2:B49""),0),1), 0)"),0.0) -> 0 | AC13: =IF(COUNTIF(B$1145:B$1305,L13)=0,0,1) -> 1 | AD13: 0 | AE13: =IFERROR(__xludf.DUMMYFUNCTION("IFERROR(IF(Match(L13,IMPORTRANGE(""https://docs.google.com/spreadsheets/d/1hvckjcCpxEuDQDPrBMml_I1kBhYyjrgR8qBKC9QGVUc/edit?resourcekey=&gid=230793720#gid=230793720"",""Form Responses 1!B2:B199""),0),1), 0)"),0.0) -> 0 | AF13: =IFERROR(__xludf.DUMMYFUNCTION("IFERROR(IF(Match(L13,IMPORTRANGE(""https://docs.google.com/spreadsheets/d/1UY0hI2S83Fmafa5P-C1LM9yqe4v4qIKTnVy_CzLzRPs/edit?resourcekey=&gid=1583835601#gid=1583835601"",""Form Responses 1!B2:B194""),0),1), 0)"),0.0) -> 0 | AG13: 0.5 | AH13: 0.5
A14: 45917.647 | B14: viraaj.vatte@warriorlife.net | C14: Viraaj | D14: Vatte | E14: G130 | F14: Novice (1st year or 2nd years who haven't placed top 10 (SCDC) or top 3 (SVCDC)) | G14: Vivian | H14: we learned about writtens and how to make our slides better | K14: Keshav Satagopan | L14: sk.satagopan@warriorlife.net | M14: Arissa Cao | N14: E | O14: 2nd Year | P14: 3 | Q14: BMOR | R14: =IF(COUNTIF(B$2:B$149,L14)=0,0,1) -> 0 | S14: =IF(COUNTIF(B$150:B$274,L14)=0,0,1) -> 0 | T14: =IF(COUNTIF(B$275:B$401,L14)=0,0,1) -> 1 | U14: =IFERROR(__xludf.DUMMYFUNCTION("IFERROR(IF(Match(L14,IMPORTRANGE(""https://docs.google.com/spreadsheets/d/1CAXKDiOnZb21bZOY_nacH9xI9AiD-nH8ZZQAwYKkVC0/edit?usp=drivesdk"",""Completed Exams!A1:A135""),0),1), 0)"),0.0) -> 0 | V14: =IF(COUNTIF(B$416:B$535,L14)=0,0,1) -> 0 | W14: =IF(COUNTIF(B$535:B$602,L14)=0,0,1) -> 1 | X14: =IF(COUNTIF(B$603:B$725,L14)=0,0,1) -> 0 | Y14: =IF(COUNTIF(B$725:B$844,L14)=0,0,1) -> 0 | Z14: =IF(COUNTIF(B$845:B$969,L14)=0,0,1) -> 1 | AA14: 0.5 | AB14: =IFERROR(__xludf.DUMMYFUNCTION("IFERROR(IF(Match(L14,IMPORTRANGE(""https://docs.google.com/spreadsheets/d/1n1sT_Q_W3mKmn2Yrd8qcNzuRD4zr4DB9gqARnjQ30B4/edit?gid=1918970062#gid=1918970062"",""Form Responses 1!B2:B49""),0),1), 0)"),0.0) -> 0 | AC14: =IF(COUNTIF(B$1145:B$1305,L14)=0,0,1) -> 1 | AD14: 0 | AE14: =IFERROR(__xludf.DUMMYFUNCTION("IFERROR(IF(Match(L14,IMPORTRANGE(""https://docs.google.com/spreadsheets/d/1hvckjcCpxEuDQDPrBMml_I1kBhYyjrgR8qBKC9QGVUc/edit?resourcekey=&gid=230793720#gid=230793720"",""Form Responses 1!B2:B199""),0),1), 0)"),0.0) -> 0 | AF14: =IFERROR(__xludf.DUMMYFUNCTION("IFERROR(IF(Match(L14,IMPORTRANGE(""https://docs.google.com/spreadsheets/d/1UY0hI2S83Fmafa5P-C1LM9yqe4v4qIKTnVy_CzLzRPs/edit?resourcekey=&gid=1583835601#gid=1583835601"",""Form Responses 1!B2:B194""),0),1), 0)"),0.0) -> 0 | AG14: =IFERROR(__xludf.DUMMYFUNCTION("IFERROR(IF(Match(L14,IMPORTRANGE(""https://docs.google.com/spreadsheets/d/1hO4mQ22n6cudUygJ2ss_JeJdm2Ua_7hJl_79lWWEtic/edit?resourcekey=&gid=2087212010#gid=2087212010"",""Form Responses 1!B2:B104""),0),1), 0)"),0.0) -> 0 | AH14: =IFERROR(__xludf.DUMMYFUNCTION("IFERROR(IF(Match(L14,IMPORTRANGE(""https://docs.google.com/spreadsheets/d/1HbfCXhSXbtTODKKY1MOFwJccyhgDKD0J9sO1k5l_6lM/edit?resourcekey=&gid=1616384832#gid=1616384832"",""Form Responses 1!E2:E143""),0),1), 0)"),0.0) -> 0
A15: 45917.647 | B15: aman.kochar@warriorlife.net | C15: Aman | D15: Kochar | E15: G130 | F15: Novice (1st year or 2nd years who haven't placed top 10 (SCDC) or top 3 (SVCDC)) | G15: Revathi | H15: i learned that when making slides you should not use many icons. | K15: Jaden Park | L15: Jaden.park@warriorlife.net | M15: Arissa Cao | N15: E | O15: 3rd Year | P15: 3 | Q15: BMOR | R15: =IF(COUNTIF(B$2:B$149,L15)=0,0,1) -> 0 | S15: =IF(COUNTIF(B$150:B$274,L15)=0,0,1) -> 0 | T15: =IF(COUNTIF(B$275:B$401,L15)=0,0,1) -> 1 | U15: =IFERROR(__xludf.DUMMYFUNCTION("IFERROR(IF(Match(L15,IMPORTRANGE(""https://docs.google.com/spreadsheets/d/1CAXKDiOnZb21bZOY_nacH9xI9AiD-nH8ZZQAwYKkVC0/edit?usp=drivesdk"",""Completed Exams!A1:A135""),0),1), 0)"),0.0) -> 0 | V15: =IF(COUNTIF(B$416:B$535,L15)=0,0,1) -> 0 | W15: =IF(COUNTIF(B$535:B$602,L15)=0,0,1) -> 0 | X15: =IF(COUNTIF(B$603:B$725,L15)=0,0,1) -> 1 | Y15: =IF(COUNTIF(B$725:B$844,L15)=0,0,1) -> 0 | Z15: =IF(COUNTIF(B$845:B$969,L15)=0,0,1) -> 0 | AA15: =IF(COUNTIF(B$971:B$1124,L15)=0,0,1) -> 1 | AB15: =IFERROR(__xludf.DUMMYFUNCTION("IFERROR(IF(Match(L15,IMPORTRANGE(""https://docs.google.com/spreadsheets/d/1n1sT_Q_W3mKmn2Yrd8qcNzuRD4zr4DB9gqARnjQ30B4/edit?gid=1918970062#gid=1918970062"",""Form Responses 1!B2:B49""),0),1), 0)"),0.0) -> 0 | AC15: =IF(COUNTIF(B$1145:B$1305,L15)=0,0,1) -> 1 | AD15: 0 | AE15: =IFERROR(__xludf.DUMMYFUNCTION("IFERROR(IF(Match(L15,IMPORTRANGE(""https://docs.google.com/spreadsheets/d/1hvckjcCpxEuDQDPrBMml_I1kBhYyjrgR8qBKC9QGVUc/edit?resourcekey=&gid=230793720#gid=230793720"",""Form Responses 1!B2:B199""),0),1), 0)"),0.0) -> 0 | AF15: =IFERROR(__xludf.DUMMYFUNCTION("IFERROR(IF(Match(L15,IMPORTRANGE(""https://docs.google.com/spreadsheets/d/1UY0hI2S83Fmafa5P-C1LM9yqe4v4qIKTnVy_CzLzRPs/edit?resourcekey=&gid=1583835601#gid=1583835601"",""Form Responses 1!B2:B194""),0),1), 0)"),0.0) -> 0 | AG15: =IFERROR(__xludf.DUMMYFUNCTION("IFERROR(IF(Match(L15,IMPORTRANGE(""https://docs.google.com/spreadsheets/d/1hO4mQ22n6cudUygJ2ss_JeJdm2Ua_7hJl_79lWWEtic/edit?resourcekey=&gid=2087212010#gid=2087212010"",""Form Responses 1!B2:B104""),0),1), 0)"),0.0) -> 0 | AH15: =IFERROR(__xludf.DUMMYFUNCTION("IFERROR(IF(Match(L15,IMPORTRANGE(""https://docs.google.com/spreadsheets/d/1HbfCXhSXbtTODKKY1MOFwJccyhgDKD0J9sO1k5l_6lM/edit?resourcekey=&gid=1616384832#gid=1616384832"",""Form Responses 1!E2:E143""),0),1), 0)"),0.0) -> 0
A16: 45917.648 | B16: avaneesh.nangare@warriorlife.net | C16: Avaneesh | D16: Nangare | E16: G130 | F16: Experienced (2nd years who have placed top 10 (SCDC) or top 3 (SVCDC) or 3rd and 4th years) | G16: Rochelle(wrong event) | H16: I learned how to brainstorm canva and more | K16: Sradha Namala | L16: sradha.namala@warriorlife.net | M16: Arissa Cao | N16: N | O16: 1st Year | P16: 3 | Q16: BMOR | R16: =IF(COUNTIF(B$2:B$149,L16)=0,0,1) -> 1 | S16: =IF(COUNTIF(B$150:B$274,L16)=0,0,1) -> 1 | T16: =IF(COUNTIF(B$275:B$401,L16)=0,0,1) -> 0 | U16: =IFERROR(__xludf.DUMMYFUNCTION("IFERROR(IF(Match(L16,IMPORTRANGE(""https://docs.google.com/spreadsheets/d/1CAXKDiOnZb21bZOY_nacH9xI9AiD-nH8ZZQAwYKkVC0/edit?usp=drivesdk"",""Completed Exams!A1:A135""),0),1), 0)"),0.0) -> 0 | V16: =IF(COUNTIF(B$416:B$535,L16)=0,0,1) -> 0 | W16: =IF(COUNTIF(B$535:B$602,L16)=0,0,1) -> 1 | X16: =IF(COUNTIF(B$603:B$725,L16)=0,0,1) -> 1 | Y16: =IF(COUNTIF(B$725:B$844,L16)=0,0,1) -> 1 | Z16: =IF(COUNTIF(B$845:B$969,L16)=0,0,1) -> 1 | AA16: =IF(COUNTIF(B$971:B$1124,L16)=0,0,1) -> 1 | AB16: =IFERROR(__xludf.DUMMYFUNCTION("IFERROR(IF(Match(L16,IMPORTRANGE(""https://docs.google.com/spreadsheets/d/1n1sT_Q_W3mKmn2Yrd8qcNzuRD4zr4DB9gqARnjQ30B4/edit?gid=1918970062#gid=1918970062"",""Form Responses 1!B2:B49""),0),1), 0)"),0.0) -> 0 | AC16: =IF(COUNTIF(B$1145:B$1305,L16)=0,0,1) -> 1 | AD16: 0 | AE16: =IFERROR(__xludf.DUMMYFUNCTION("IFERROR(IF(Match(L16,IMPORTRANGE(""https://docs.google.com/spreadsheets/d/1hvckjcCpxEuDQDPrBMml_I1kBhYyjrgR8qBKC9QGVUc/edit?resourcekey=&gid=230793720#gid=230793720"",""Form Responses 1!B2:B199""),0),1), 0)"),0.0) -> 0 | AF16: 0.5 | AG16: 0.5 | AH16: =IFERROR(__xludf.DUMMYFUNCTION("IFERROR(IF(Match(L16,IMPORTRANGE(""https://docs.google.com/spreadsheets/d/1HbfCXhSXbtTODKKY1MOFwJccyhgDKD0J9sO1k5l_6lM/edit?resourcekey=&gid=1616384832#gid=1616384832"",""Form Responses 1!E2:E143""),0),1), 0)"),0.0) -> 0
A17: 45917.648 | B17: aditya.poduri@warriorlife.net | C17: Aditya | D17: Poduri | E17: G130 | F17: Novice (1st year or 2nd years who haven't placed top 10 (SCDC) or top 3 (SVCDC)) | G17: Elaine Wang | H17: Do not add too many icons when making your presentation, that can end up becoming redundant and repetitive. | K17: Franklin Dao | L17: franklin.dao@warriorlife.net | M17: Ayden Wang | N17: E | O17: 3rd Year | P17: 4 | Q17: HTOR | R17: =IF(COUNTIF(B$2:B$149,L17)=0,0,1) -> 1 | S17: =IF(COUNTIF(B$150:B$274,L17)=0,0,1) -> 0 | T17: =IF(COUNTIF(B$275:B$401,L17)=0,0,1) -> 0 | U17: =IFERROR(__xludf.DUMMYFUNCTION("IFERROR(IF(Match(L17,IMPORTRANGE(""https://docs.google.com/spreadsheets/d/1CAXKDiOnZb21bZOY_nacH9xI9AiD-nH8ZZQAwYKkVC0/edit?usp=drivesdk"",""Completed Exams!A1:A135""),0),1), 0)"),0.0) -> 0 | V17: =IF(COUNTIF(B$416:B$535,L17)=0,0,1) -> 0 | W17: =IF(COUNTIF(B$535:B$602,L17)=0,0,1) -> 0 | X17: =IF(COUNTIF(B$603:B$725,L17)=0,0,1) -> 1 | Y17: =IF(COUNTIF(B$725:B$844,L17)=0,0,1) -> 0 | Z17: =IF(COUNTIF(B$845:B$969,L17)=0,0,1) -> 0 | AA17: =IF(COUNTIF(B$971:B$1124,L17)=0,0,1) -> 1 | AB17: =IFERROR(__xludf.DUMMYFUNCTION("IFERROR(IF(Match(L17,IMPORTRANGE(""https://docs.google.com/spreadsheets/d/1n1sT_Q_W3mKmn2Yrd8qcNzuRD4zr4DB9gqARnjQ30B4/edit?gid=1918970062#gid=1918970062"",""Form Responses 1!B2:B49""),0),1), 0)"),0.0) -> 0 | AC17: =IF(COUNTIF(B$1145:B$1305,L17)=0,0,1) -> 1 | AD17: 1 | AE17: =IFERROR(__xludf.DUMMYFUNCTION("IFERROR(IF(Match(L17,IMPORTRANGE(""https://docs.google.com/spreadsheets/d/1hvckjcCpxEuDQDPrBMml_I1kBhYyjrgR8qBKC9QGVUc/edit?resourcekey=&gid=230793720#gid=230793720"",""Form Responses 1!B2:B199""),0),1), 0)"),0.0) -> 0 | AF17: =IFERROR(__xludf.DUMMYFUNCTION("IFERROR(IF(Match(L17,IMPORTRANGE(""https://docs.google.com/spreadsheets/d/1UY0hI2S83Fmafa5P-C1LM9yqe4v4qIKTnVy_CzLzRPs/edit?resourcekey=&gid=1583835601#gid=1583835601"",""Form Responses 1!B2:B194""),0),1), 0)"),0.0) -> 0 | AG17: =IFERROR(__xludf.DUMMYFUNCTION("IFERROR(IF(Match(L17,IMPORTRANGE(""https://docs.google.com/spreadsheets/d/1hO4mQ22n6cudUygJ2ss_JeJdm2Ua_7hJl_79lWWEtic/edit?resourcekey=&gid=2087212010#gid=2087212010"",""Form Responses 1!B2:B104""),0),1), 0)"),0.0) -> 0 | AH17: =IFERROR(__xludf.DUMMYFUNCTION("IFERROR(IF(Match(L17,IMPORTRANGE(""https://docs.google.com/spreadsheets/d/1HbfCXhSXbtTODKKY1MOFwJccyhgDKD0J9sO1k5l_6lM/edit?resourcekey=&gid=1616384832#gid=1616384832"",""Form Responses 1!E2:E143""),0),1), 0)"),0.0) -> 0
A18: 45917.648 | B18: sarah.xu@warriorlife.net | C18: Sarah | D18: Xu | E18: G130 | F18: Experienced (2nd years who have placed top 10 (SCDC) or top 3 (SVCDC) or 3rd and 4th years) | G18: Suneri Chinthalapati | H18: Don’t cram too much information on slides, and don’t use too many icons. | K18: Samuel Xiao | L18: samuel.xiao@warriorlife.net | M18: Ayden Wang | N18: E | O18: 3rd Year | P18: 4 | Q18: HTOR | R18: =IF(COUNTIF(B$2:B$149,L18)=0,0,1) -> 1 | S18: =IF(COUNTIF(B$150:B$274,L18)=0,0,1) -> 0 | T18: =IF(COUNTIF(B$275:B$401,L18)=0,0,1) -> 0 | U18: =IFERROR(__xludf.DUMMYFUNCTION("IFERROR(IF(Match(L18,IMPORTRANGE(""https://docs.google.com/spreadsheets/d/1CAXKDiOnZb21bZOY_nacH9xI9AiD-nH8ZZQAwYKkVC0/edit?usp=drivesdk"",""Completed Exams!A1:A135""),0),1), 0)"),0.0) -> 0 | V18: =IF(COUNTIF(B$416:B$535,L18)=0,0,1) -> 0 | W18: =IF(COUNTIF(B$535:B$602,L18)=0,0,1) -> 1 | X18: =IF(COUNTIF(B$603:B$725,L18)=0,0,1) -> 1 | Y18: =IF(COUNTIF(B$725:B$844,L18)=0,0,1) -> 0 | Z18: =IF(COUNTIF(B$845:B$969,L18)=0,0,1) -> 1 | AA18: =IF(COUNTIF(B$971:B$1124,L18)=0,0,1) -> 1 | AB18: 1 | AC18: =IF(COUNTIF(B$1145:B$1305,L18)=0,0,1) -> 1 | AD18: 1 | AE18: =IFERROR(__xludf.DUMMYFUNCTION("IFERROR(IF(Match(L18,IMPORTRANGE(""https://docs.google.com/spreadsheets/d/1hvckjcCpxEuDQDPrBMml_I1kBhYyjrgR8qBKC9QGVUc/edit?resourcekey=&gid=230793720#gid=230793720"",""Form Responses 1!B2:B199""),0),1), 0)"),0.0) -> 0 | AF18: =IFERROR(__xludf.DUMMYFUNCTION("IFERROR(IF(Match(L18,IMPORTRANGE(""https://docs.google.com/spreadsheets/d/1UY0hI2S83Fmafa5P-C1LM9yqe4v4qIKTnVy_CzLzRPs/edit?resourcekey=&gid=1583835601#gid=1583835601"",""Form Responses 1!B2:B194""),0),1), 0)"),0.0) -> 0 | AG18: =IFERROR(__xludf.DUMMYFUNCTION("IFERROR(IF(Match(L18,IMPORTRANGE(""https://docs.google.com/spreadsheets/d/1hO4mQ22n6cudUygJ2ss_JeJdm2Ua_7hJl_79lWWEtic/edit?resourcekey=&gid=2087212010#gid=2087212010"",""Form Responses 1!B2:B104""),0),1), 0)"),0.0) -> 0 | AH18: =IFERROR(__xludf.DUMMYFUNCTION("IFERROR(IF(Match(L18,IMPORTRANGE(""https://docs.google.com/spreadsheets/d/1HbfCXhSXbtTODKKY1MOFwJccyhgDKD0J9sO1k5l_6lM/edit?resourcekey=&gid=1616384832#gid=1616384832"",""Form Responses 1!E2:E143""),0),1), 0)"),0.0) -> 0
A19: 45917.65 | B19: jessica.ma@warriorlife.net | C19: Jessica | D19: Ma | E19: G130 | F19: Novice (1st year or 2nd years who haven't placed top 10 (SCDC) or top 3 (SVCDC)) | G19: Emily Tang | H19: I learned that I have to find a company that is good in all aspects except their social media branding. | K19: Aubrey Santos | L19: aubrey.santos@warriorlife.net | M19: Ayden Wang | N19: N | O19: 1st Year | P19: 4 | Q19: SEOR | R19: =IF(COUNTIF(B$2:B$149,L19)=0,0,1) -> 1 | S19: =IF(COUNTIF(B$150:B$274,L19)=0,0,1) -> 1 | T19: =IF(COUNTIF(B$275:B$401,L19)=0,0,1) -> 1 | U19: =IFERROR(__xludf.DUMMYFUNCTION("IFERROR(IF(Match(L19,IMPORTRANGE(""https://docs.google.com/spreadsheets/d/1CAXKDiOnZb21bZOY_nacH9xI9AiD-nH8ZZQAwYKkVC0/edit?usp=drivesdk"",""Completed Exams!A1:A135""),0),1), 0)"),0.0) -> 0 | V19: =IF(COUNTIF(B$416:B$535,L19)=0,0,1) -> 1 | W19: 1 | X19: =IF(COUNTIF(B$603:B$725,L19)=0,0,1) -> 1 | Y19: 0.5 | Z19: =IF(COUNTIF(B$845:B$969,L19)=0,0,1) -> 1 | AA19: =IF(COUNTIF(B$971:B$1124,L19)=0,0,1) -> 1 | AB19: =IFERROR(__xludf.DUMMYFUNCTION("IFERROR(IF(Match(L19,IMPORTRANGE(""https://docs.google.com/spreadsheets/d/1n1sT_Q_W3mKmn2Yrd8qcNzuRD4zr4DB9gqARnjQ30B4/edit?gid=1918970062#gid=1918970062"",""Form Responses 1!B2:B49""),0),1), 0)"),0.0) -> 0 | AC19: =IF(COUNTIF(B$1145:B$1305,L19)=0,0,1) -> 1 | AD19: 1 | AE19: =IFERROR(__xludf.DUMMYFUNCTION("IFERROR(IF(Match(L19,IMPORTRANGE(""https://docs.google.com/spreadsheets/d/1hvckjcCpxEuDQDPrBMml_I1kBhYyjrgR8qBKC9QGVUc/edit?resourcekey=&gid=230793720#gid=230793720"",""Form Responses 1!B2:B199""),0),1), 0)"),0.0) -> 0 | AF19: =IFERROR(__xludf.DUMMYFUNCTION("IFERROR(IF(Match(L19,IMPORTRANGE(""https://docs.google.com/spreadsheets/d/1UY0hI2S83Fmafa5P-C1LM9yqe4v4qIKTnVy_CzLzRPs/edit?resourcekey=&gid=1583835601#gid=1583835601"",""Form Responses 1!B2:B194""),0),1), 0)"),0.0) -> 0 | AG19: =IFERROR(__xludf.DUMMYFUNCTION("IFERROR(IF(Match(L19,IMPORTRANGE(""https://docs.google.com/spreadsheets/d/1hO4mQ22n6cudUygJ2ss_JeJdm2Ua_7hJl_79lWWEtic/edit?resourcekey=&gid=2087212010#gid=2087212010"",""Form Responses 1!B2:B104""),0),1), 0)"),0.0) -> 0 | AH19: =IFERROR(__xludf.DUMMYFUNCTION("IFERROR(IF(Match(L19,IMPORTRANGE(""https://docs.google.com/spreadsheets/d/1HbfCXhSXbtTODKKY1MOFwJccyhgDKD0J9sO1k5l_6lM/edit?resourcekey=&gid=1616384832#gid=1616384832"",""Form Responses 1!E2:E143""),0),1), 0)"),0.0) -> 0
A20: 45917.661 | B20: aidan.qi@warriorlife.net | C20: Aidan | D20: Qi | E20: G107 | F20: Experienced (2nd years who have placed top 10 (SCDC) or top 3 (SVCDC) or 3rd and 4th years) | G20: Saron | H20: Elaine and Evelyn | K20: Riyana Baldua | L20: riyana.baldua@warriorlife.net | M20: Ayden Wang | N20: N | O20: 2nd Year | P20: 4 | Q20: SEOR | R20: =IF(COUNTIF(B$2:B$149,L20)=0,0,1) -> 1 | S20: =IF(COUNTIF(B$150:B$274,L20)=0,0,1) -> 1 | T20: =IF(COUNTIF(B$275:B$401,L20)=0,0,1) -> 1 | U20: =IFERROR(__xludf.DUMMYFUNCTION("IFERROR(IF(Match(L20,IMPORTRANGE(""https://docs.google.com/spreadsheets/d/1CAXKDiOnZb21bZOY_nacH9xI9AiD-nH8ZZQAwYKkVC0/edit?usp=drivesdk"",""Completed Exams!A1:A135""),0),1), 0)"),0.0) -> 0 | V20: =IF(COUNTIF(B$416:B$535,L20)=0,0,1) -> 1 | W20: 1 | X20: =IF(COUNTIF(B$603:B$725,L20)=0,0,1) -> 1 | Y20: 1 | Z20: =IF(COUNTIF(B$845:B$969,L20)=0,0,1) -> 1 | AA20: =IF(COUNTIF(B$971:B$1124,L20)=0,0,1) -> 1 | AB20: =IFERROR(__xludf.DUMMYFUNCTION("IFERROR(IF(Match(L20,IMPORTRANGE(""https://docs.google.com/spreadsheets/d/1n1sT_Q_W3mKmn2Yrd8qcNzuRD4zr4DB9gqARnjQ30B4/edit?gid=1918970062#gid=1918970062"",""Form Responses 1!B2:B49""),0),1), 0)"),0.0) -> 0 | AC20: =IF(COUNTIF(B$1145:B$1305,L20)=0,0,1) -> 1 | AD20: 1 | AE20: =IFERROR(__xludf.DUMMYFUNCTION("IFERROR(IF(Match(L20,IMPORTRANGE(""https://docs.google.com/spreadsheets/d/1hvckjcCpxEuDQDPrBMml_I1kBhYyjrgR8qBKC9QGVUc/edit?resourcekey=&gid=230793720#gid=230793720"",""Form Responses 1!B2:B199""),0),1), 0)"),0.0) -> 0 | AF20: =IFERROR(__xludf.DUMMYFUNCTION("IFERROR(IF(Match(L20,IMPORTRANGE(""https://docs.google.com/spreadsheets/d/1UY0hI2S83Fmafa5P-C1LM9yqe4v4qIKTnVy_CzLzRPs/edit?resourcekey=&gid=1583835601#gid=1583835601"",""Form Responses 1!B2:B194""),0),1), 0)"),0.0) -> 0 | AG20: =IFERROR(__xludf.DUMMYFUNCTION("IFERROR(IF(Match(L20,IMPORTRANGE(""https://docs.google.com/spreadsheets/d/1hO4mQ22n6cudUygJ2ss_JeJdm2Ua_7hJl_79lWWEtic/edit?resourcekey=&gid=2087212010#gid=2087212010"",""Form Responses 1!B2:B104""),0),1), 0)"),0.0) -> 0 | AH20: 0.5
A21: 45917.662 | B21: jennaly.fangonilo@warriorlife.net | C21: JennaLy | D21: Fangonilo | E21: G107 | F21: Experienced (2nd years who have placed top 10 (SCDC) or top 3 (SVCDC) or 3rd and 4th years) | G21: Lizzy | H21: Elaine and Evelyn | K21: Maahir Satwani | L21: maahir.satwani@warriorlife.net | M21: Ayden Wang | N21: N | O21: 1st Year | P21: 4 | Q21: IMCS | R21: =IF(COUNTIF(B$2:B$149,L21)=0,0,1) -> 1 | S21: =IF(COUNTIF(B$150:B$274,L21)=0,0,1) -> 1 | T21: 0.5 | U21: =IFERROR(__xludf.DUMMYFUNCTION("IFERROR(IF(Match(L21,IMPORTRANGE(""https://docs.google.com/spreadsheets/d/1CAXKDiOnZb21bZOY_nacH9xI9AiD-nH8ZZQAwYKkVC0/edit?usp=drivesdk"",""Completed Exams!A1:A135""),0),1), 0)"),0.0) -> 0 | V21: 0.5 | W21: =IF(COUNTIF(B$535:B$602,L21)=0,0,1) -> 0 | X21: =IF(COUNTIF(B$603:B$725,L21)=0,0,1) -> 1 | Y21: =IF(COUNTIF(B$725:B$844,L21)=0,0,1) -> 1 | Z21: =IF(COUNTIF(B$845:B$969,L21)=0,0,1) -> 1 | AA21: =IF(COUNTIF(B$971:B$1124,L21)=0,0,1) -> 1 | AB21: 1 | AC21: =IF(COUNTIF(B$1145:B$1305,L21)=0,0,1) -> 1 | AD21: 1 | AE21: 0.5 | AF21: =IFERROR(__xludf.DUMMYFUNCTION("IFERROR(IF(Match(L21,IMPORTRANGE(""https://docs.google.com/spreadsheets/d/1UY0hI2S83Fmafa5P-C1LM9yqe4v4qIKTnVy_CzLzRPs/edit?resourcekey=&gid=1583835601#gid=1583835601"",""Form Responses 1!B2:B194""),0),1), 0)"),0.0) -> 0 | AG21: =IFERROR(__xludf.DUMMYFUNCTION("IFERROR(IF(Match(L21,IMPORTRANGE(""https://docs.google.com/spreadsheets/d/1hO4mQ22n6cudUygJ2ss_JeJdm2Ua_7hJl_79lWWEtic/edit?resourcekey=&gid=2087212010#gid=2087212010"",""Form Responses 1!B2:B104""),0),1), 0)"),0.0) -> 0 | AH21: =IFERROR(__xludf.DUMMYFUNCTION("IFERROR(IF(Match(L21,IMPORTRANGE(""https://docs.google.com/spreadsheets/d/1HbfCXhSXbtTODKKY1MOFwJccyhgDKD0J9sO1k5l_6lM/edit?resourcekey=&gid=1616384832#gid=1616384832"",""Form Responses 1!E2:E143""),0),1), 0)"),0.0) -> 0
A22: 45917.662 | B22: john.kirchenbauer@warriorlife.net | C22: John | D22: Kirchenbauer | E22: G107 | F22: Novice (1st year or 2nd years who haven't placed top 10 (SCDC) or top 3 (SVCDC)) | G22: Melody | H22: Elaine, Evelyn | K22: Suvir Maniktala | L22: suvir.maniktala@warriorlife.net | M22: Ayden Wang | N22: N | O22: 2nd Year | P22: 4 | Q22: IMCS | R22: =IF(COUNTIF(B$2:B$149,L22)=0,0,1) -> 1 | S22: =IF(COUNTIF(B$150:B$274,L22)=0,0,1) -> 1 | T22: =IF(COUNTIF(B$275:B$401,L22)=0,0,1) -> 1 | U22: =IFERROR(__xludf.DUMMYFUNCTION("IFERROR(IF(Match(L22,IMPORTRANGE(""https://docs.google.com/spreadsheets/d/1CAXKDiOnZb21bZOY_nacH9xI9AiD-nH8ZZQAwYKkVC0/edit?usp=drivesdk"",""Completed Exams!A1:A135""),0),1), 0)"),0.0) -> 0 | V22: =IF(COUNTIF(B$416:B$535,L22)=0,0,1) -> 1 | W22: =IF(COUNTIF(B$535:B$602,L22)=0,0,1) -> 0 | X22: =IF(COUNTIF(B$603:B$725,L22)=0,0,1) -> 1 | Y22: =IF(COUNTIF(B$725:B$844,L22)=0,0,1) -> 1 | Z22: =IF(COUNTIF(B$845:B$969,L22)=0,0,1) -> 1 | AA22: =IF(COUNTIF(B$971:B$1124,L22)=0,0,1) -> 1 | AB22: =IFERROR(__xludf.DUMMYFUNCTION("IFERROR(IF(Match(L22,IMPORTRANGE(""https://docs.google.com/spreadsheets/d/1n1sT_Q_W3mKmn2Yrd8qcNzuRD4zr4DB9gqARnjQ30B4/edit?gid=1918970062#gid=1918970062"",""Form Responses 1!B2:B49""),0),1), 0)"),0.0) -> 0 | AC22: =IF(COUNTIF(B$1145:B$1305,L22)=0,0,1) -> 1 | AD22: 1 | AE22: =IFERROR(__xludf.DUMMYFUNCTION("IFERROR(IF(Match(L22,IMPORTRANGE(""https://docs.google.com/spreadsheets/d/1hvckjcCpxEuDQDPrBMml_I1kBhYyjrgR8qBKC9QGVUc/edit?resourcekey=&gid=230793720#gid=230793720"",""Form Responses 1!B2:B199""),0),1), 0)"),0.0) -> 0 | AF22: =IFERROR(__xludf.DUMMYFUNCTION("IFERROR(IF(Match(L22,IMPORTRANGE(""https://docs.google.com/spreadsheets/d/1UY0hI2S83Fmafa5P-C1LM9yqe4v4qIKTnVy_CzLzRPs/edit?resourcekey=&gid=1583835601#gid=1583835601"",""Form Responses 1!B2:B194""),0),1), 0)"),0.0) -> 0 | AG22: =IFERROR(__xludf.DUMMYFUNCTION("IFERROR(IF(Match(L22,IMPORTRANGE(""https://docs.google.com/spreadsheets/d/1hO4mQ22n6cudUygJ2ss_JeJdm2Ua_7hJl_79lWWEtic/edit?resourcekey=&gid=2087212010#gid=2087212010"",""Form Responses 1!B2:B104""),0),1), 0)"),0.0) -> 0 | AH22: =IFERROR(__xludf.DUMMYFUNCTION("IFERROR(IF(Match(L22,IMPORTRANGE(""https://docs.google.com/spreadsheets/d/1HbfCXhSXbtTODKKY1MOFwJccyhgDKD0J9sO1k5l_6lM/edit?resourcekey=&gid=1616384832#gid=1616384832"",""Form Responses 1!E2:E143""),0),1), 0)"),0.0) -> 0
A23: 45917.662 | B23: crystal.chen@warriorlife.net | C23: Crystal | D23: Chen | E23: G107 | F23: Novice (1st year or 2nd years who haven't placed top 10 (SCDC) or top 3 (SVCDC)) | G23: Philina Chen | H23: Elaine and Evelyn | K23: Ethan Teh | L23: ethan.teh@warriorlife.net | M23: Chloe Ding | N23: N | O23: 2nd Year | P23: 5 | Q23: EIB | R23: =IF(COUNTIF(B$2:B$149,L23)=0,0,1) -> 1 | S23: =IF(COUNTIF(B$150:B$274,L23)=0,0,1) -> 0 | T23: =IF(COUNTIF(B$275:B$401,L23)=0,0,1) -> 1 | U23: =IFERROR(__xludf.DUMMYFUNCTION("IFERROR(IF(Match(L23,IMPORTRANGE(""https://docs.google.com/spreadsheets/d/1CAXKDiOnZb21bZOY_nacH9xI9AiD-nH8ZZQAwYKkVC0/edit?usp=drivesdk"",""Completed Exams!A1:A135""),0),1), 0)"),0.0) -> 0 | V23: =IF(COUNTIF(B$416:B$535,L23)=0,0,1) -> 1 | W23: =IF(COUNTIF(B$535:B$602,L23)=0,0,1) -> 0 | X23: =IF(COUNTIF(B$603:B$725,L23)=0,0,1) -> 1 | Y23: =IF(COUNTIF(B$725:B$844,L23)=0,0,1) -> 1 | Z23: =IF(COUNTIF(B$845:B$969,L23)=0,0,1) -> 1 | AA23: =IF(COUNTIF(B$971:B$1124,L23)=0,0,1) -> 1 | AB23: =IFERROR(__xludf.DUMMYFUNCTION("IFERROR(IF(Match(L23,IMPORTRANGE(""https://docs.google.com/spreadsheets/d/1n1sT_Q_W3mKmn2Yrd8qcNzuRD4zr4DB9gqARnjQ30B4/edit?gid=1918970062#gid=1918970062"",""Form Responses 1!B2:B49""),0),1), 0)"),0.0) -> 0 | AC23: =IF(COUNTIF(B$1145:B$1305,L23)=0,0,1) -> 1 | AD23: 0 | AE23: =IFERROR(__xludf.DUMMYFUNCTION("IFERROR(IF(Match(L23,IMPORTRANGE(""https://docs.google.com/spreadsheets/d/1hvckjcCpxEuDQDPrBMml_I1kBhYyjrgR8qBKC9QGVUc/edit?resourcekey=&gid=230793720#gid=230793720"",""Form Responses 1!B2:B199""),0),1), 0)"),0.0) -> 0 | AF23: =IFERROR(__xludf.DUMMYFUNCTION("IFERROR(IF(Match(L23,IMPORTRANGE(""https://docs.google.com/spreadsheets/d/1UY0hI2S83Fmafa5P-C1LM9yqe4v4qIKTnVy_CzLzRPs/edit?resourcekey=&gid=1583835601#gid=1583835601"",""Form Responses 1!B2:B194""),0),1), 0)"),0.0) -> 0 | AG23: =IFERROR(__xludf.DUMMYFUNCTION("IFERROR(IF(Match(L23,IMPORTRANGE(""https://docs.google.com/spreadsheets/d/1hO4mQ22n6cudUygJ2ss_JeJdm2Ua_7hJl_79lWWEtic/edit?resourcekey=&gid=2087212010#gid=2087212010"",""Form Responses 1!B2:B104""),0),1), 0)"),0.0) -> 0 | AH23: =IFERROR(__xludf.DUMMYFUNCTION("IFERROR(IF(Match(L23,IMPORTRANGE(""https://docs.google.com/spreadsheets/d/1HbfCXhSXbtTODKKY1MOFwJccyhgDKD0J9sO1k5l_6lM/edit?resourcekey=&gid=1616384832#gid=1616384832"",""Form Responses 1!E2:E143""),0),1), 0)"),0.0) -> 0
